Failed to Update Record with userName run12 and userId331c251d-0c56-42bb-a20b-d1d16ca825e8 and error Message is {"id":"api.user.update","ver":"v1","ts":"2019-05-23 18:26:38:720+0530","params":{"resmsgid":null,"msgid":"eecf5daa-766a-4e09-aca9-ee61e2b637d6","err":"EXTERNALID_ASSIGNED_TO_OTHER_USER","status":"EXTERNALID_ASSIGNED_TO_OTHER_USER","errmsg":"External ID (id: ext12, idType: channel_0001, provider: channel_0001) already assigned to another user."},"responseCode":"CLIENT_ERROR","result":{}}
